Workbook

Sheet Formulário
B2: FORMULÁRIO DE QUEBRAS
B9: DEPARTAMENTO DE: | D9: QBSP
B10: EMPRESA: | D10: GN53
B11: CENTRO DE CUSTO: | D11: 4303010107
B12: DATA: | D12: 46253
B14: DEPÓSITO | C14: CÓDIGO | D14: LOTE | E14: DESIGNAÇÃO | F14: QUANTIDADE | H14: UMB | I14: MOTIVO
B15: 0099 | C15: 7802415 | D15: 6275429 | E15: DELTA TIMOR COFFEE MU 250g | F15: 16 | H15: UN | I15: 1
B16: 0099 | C16: 7805018 | D16: 6280178 | E16: DELTA Q EPIQ COFFEE 10CAP | F16: 12 | H16: UN | I16: 4
B17: 0099 | C17: 7805021 | D17: 6281694 | E17: DELTA Q QHARISMA COFFEE 10CAP | F17: 144 | H17: UN | I17: 4
B18: 0099 | C18: 7805023 | D18: 6281481 | E18: DELTA Q AQTIVUS COFFEE 10CAP | F18: 36 | H18: UN | I18: 4
B19: 0099 | C19: 7805110 | D19: 6281442 | E19: DELTA Q COLÔMBIA COFFEE 10CA | F19: 12 | H19: UN | I19: 4
B20: 0099 | C20: 7822851 | D20: 6285179 | E20: DELTA Q QALIDUS DECAF COFFEE 10 CAP | F20: 24 | H20: UN | I20: 4
B21: 0099 | C21: 7822851 | D21: 6280132 | E21: DELTA Q QALIDUS DECAF COFFEE 10 CAP | F21: 60 | H21: UN | I21: 4
B22: 0099 | C22: 851056 | D22: 83620 | E22: =IFERROR(VLOOKUP(C22,Folha2!$A$1:$E$1300,2,0),"") -> TREMOÇO EXTRA (13/15) FRASCO 235 g | F22: 84 | H22: =IFERROR(VLOOKUP(C22,Folha2!A:C,3,0),"") -> UN | I22: 4
E23: =IFERROR(VLOOKUP(C23,Folha2!$A$1:$E$1300,2,0),"") | H23: =IFERROR(VLOOKUP(C23,Folha2!A:C,3,0),"")
E24: =IFERROR(VLOOKUP(C24,Folha2!$A$1:$E$1300,2,0),"") | H24: =IFERROR(VLOOKUP(C24,Folha2!A:C,3,0),"")
E25: =IFERROR(VLOOKUP(C25,Folha2!$A$1:$E$1300,2,0),"") | H25: =IFERROR(VLOOKUP(C25,Folha2!A:C,3,0),"")
E26: =IFERROR(VLOOKUP(C26,Folha2!$A$1:$E$1300,2,0),"") | H26: =IFERROR(VLOOKUP(C26,Folha2!A:C,3,0),"")
E27: =IFERROR(VLOOKUP(C27,Folha2!$A$1:$E$1300,2,0),"") | H27: =IFERROR(VLOOKUP(C27,Folha2!A:C,3,0),"")
E28: =IFERROR(VLOOKUP(C28,Folha2!$A$1:$E$1300,2,0),"") | H28: =IFERROR(VLOOKUP(C28,Folha2!A:C,3,0),"")
E29: =IFERROR(VLOOKUP(C29,Folha2!$A$1:$E$1300,2,0),"") | H29: =IFERROR(VLOOKUP(C29,Folha2!A:C,3,0),"")
E30: =IFERROR(VLOOKUP(C30,Folha2!$A$1:$E$1300,2,0),"") | H30: =IFERROR(VLOOKUP(C30,Folha2!A:C,3,0),"")
E31: =IFERROR(VLOOKUP(C31,Folha2!$A$1:$E$1300,2,0),"") | H31: =IFERROR(VLOOKUP(C31,Folha2!A:C,3,0),"")
E32: =IFERROR(VLOOKUP(C32,Folha2!$A$1:$E$1300,2,0),"") | H32: =IFERROR(VLOOKUP(C32,Folha2!A:C,3,0),"")
E33: =IFERROR(VLOOKUP(C33,Folha2!$A$1:$E$1300,2,0),"") | H33: =IFERROR(VLOOKUP(C33,Folha2!A:C,3,0),"")
E34: =IFERROR(VLOOKUP(C34,Folha2!$A$1:$E$1300,2,0),"") | H34: =IFERROR(VLOOKUP(C34,Folha2!A:C,3,0),"")
... E39: =IFERROR(VLOOKUP(C39,Folha2!$A$1:$E$1300,2,0),"") | H39: =IFERROR(VLOOKUP(C39,Folha2!A:C,3,0),"")
B43: MOTIVOS DA QUEBRA*
B44: 1. | C44: Danificado em armazém
B45: 2. | C45: Danificado na distribuição
B46: 3. | C46: Danificado na receção
B47: 4. | C47: Validade expirada
B48: 5. | C48: Outros
B51: OBSERVAÇÕES:
H58: (Se aplicável)
C59: Resp. logístico | E59: Aprovação (1) | H59: Aprovação (2)
B63: Tempo de Arquivo : 10 anos
B64: Local e resp.Pelo arquivo: Armazém / Responsavél do Armazém
B65: MR 1063.00

Sheet Folha2
A1: 11825 | B1: DELTA OFFICE CÁP. ROYAL NAT 75UN | C1: CX | D1: MRQL | E1: 6
A2: 11825 | B2: DELTA OFFICE CÁP. ROYAL NAT 75UN | C2: CX | D2: MRQL | E2: 6
A3: 11825 | B3: DELTA OFFICE CÁP. ROYAL NAT 75UN | C3: CX | D3: MRQL | E3: 6
A4: 11825 | B4: DELTA OFFICE CÁP. ROYAL NAT 75UN | C4: CX | D4: MRQL | E4: 6
A5: 11827 | B5: DELTA OFFICE PAST. EXECUTIVE 75UN | C5: CX | D5: MRQL | E5: 6
A6: 12115 | B6: CAPSULINO DELTA Q | C6: UN | D6: MRQL | E6: 6
A7: 12193 | B7: MAQ. MILKQOOL EVOLUTION BRN | C7: UN | D7: MRQL | E7: 6
A8: 12193 | B8: MAQ. MILKQOOL EVOLUTION BRN | C8: UN | D8: MRQL | E8: 6
A9: 12260 | B9: MAQ QOOL EVOLUTION VITOR SOBRAL | C9: UN | D9: MRQL | E9: 6
A10: 12290 | B10: COPO DELTA Q_DIM 87 ML Business (Mang | C10: UN | D10: MRQL | E10: 6
A11: 12681 | B11: DELTA Q BUSINESS CHAV CAFÉ | C11: UN | D11: MRQL | E11: 6
A12: 12682 | B12: DELTA Q BUSINESS CHAV ½ LEITE | C12: UN | D12: MRQL | E12: 6
... A1070: 851102 | B1070: MARMELADA FIBRA QAMPO 330g | C1070: UN | D1070: MRQL | E1070: 6
A1071: C-610004217 | B1071: DETERGENTE GRUPO CX (150 PASTILHAS) | C1071: UN | D1071: MRQL | E1071: 6
A1072: F122300 | B1072: DETERGENTE L.GRUPOS(1 EMB.=180 DOSES) | C1072: UN | D1072: MRQL | E1072: 6
A1073: FFCF-10 | B1073: FILTRO FCF 10-(CAIXAS/500) | C1073: UN | D1073: MRQL | E1073: 6
A1074: FFCF-2 | B1074: FILTRO DA FCF 2 - (CAIXA/1000) | C1074: UN | D1074: MRQL | E1074: 6
A1075: FFCF-20 | B1075: FILTRO FCF 20 (CX 500) | C1075: UN | D1075: MRQL | E1075: 6
A1076: FFCF-5 | B1076: FILTRO DA FCF 5 - (CAIXAS/500) | C1076: UN | D1076: MRQL | E1076: 6
A1077: IB-8977 | B1077: ESCOVA DE LIMPEZA | C1077: UN | D1077: MRQL | E1077: 6
A1078: MO-00901/04 | B1078: LEITEIRA 50 CL EM AÇO INOX | C1078: UN | D1078: MRQL | E1078: 6
A1079: MO-660/B | B1079: LAPIS DE DECORAÇÃO AZUL | C1079: UN | D1079: MRQL | E1079: 6
A1080: R-I2 | B1080: PÓ DE LIMPEZA (SAQUET.30G) | C1080: UN | D1080: MRQL | E1080: 6
A1081: Z-962961 | B1081: PASTILHAS LIMP. PARA MAQ.KARISMA(CX10 | C1081: CX | D1081: MRQL | E1081: 6
A1082: 17370 | B1082: EXPOSITOR CAPSULAS DELTAQ - GASOLINEI | C1082: UN | D1082: MRQL | E1082: 6
A1083: 1028911 | B1083: ABRE CAPSULAS MANUAL BECK'S | C1083: UN | D1083: MRQL | E1083: 6
A1084: 1042500 | B1084: BASE COPO BECKS C/100 | C1084: UN | D1084: MRQL | E1084: 6
A1085: 1042501 | B1085: BAR RUNNER BECKS | C1085: UN | D1085: MRQL | E1085: 6
A1086: 1042505 | B1086: COPO FRANZISKANER 0,30 CL | C1086: UN | D1086: MRQL | E1086: 6
A1087: 1048012 | B1087: COPO FRANZISKANER 0,50 CL | C1087: UN | D1087: MRQL | E1087: 6
A1088: 1048017 | B1088: COPO PLÁSTICO TETLEY 250 ML | C1088: UN | D1088: MRQL | E1088: 6
A1089: 1048018 | B1089: COPO DE VIDRO TETLEY 340 ML | C1089: UN | D1089: MRQL | E1089: 6
A1090: 1048674 | B1090: EXPOSITOR BALCÃO BECK'S GARRAFA | C1090: UN | D1090: MRQL | E1090: 6
A1091: 1048678 | B1091: COPO LWBRAU 30 CL | C1091: UN | D1091: MRQL | E1091: 6
A1092: 1048938 | B1092: COPO PLÁSTICO BECKS 20 CL | C1092: UN | D1092: MRQL | E1092: 6
A1093: 1049710 | B1093: COPO STELA ARTOIS 50 CL | C1093: UN | D1093: MRQL | E1093: 6
... A1224: 1058083 | B1224: GO CHILL MULTI PACK 2+1 (2CAP + 1 CAR | C1224: PAK | D1224: MRQL | E1224: 6
A1225: 1058084 | B1225: LATTE MACCHIATO S/LACTOS GO CHILL 230 | C1225: UN
A1226: 1048006 | B1226: KIT VISIBILIDADE PERFECT DRAFT BECK'S | C1226: UN
A1227: 701620 | B1227: VRA AM CAIADO BC2022 750ML | C1227: UN
...
